Traceback (most recent call last):
  File "D:\Anaconda3\Lib\site-packages\jupyter_cache\executors\utils.py", line 58, in single_nb_execution
    executenb(
  File "D:\Anaconda3\Lib\site-packages\nbclient\client.py", line 1305, in execute
    return NotebookClient(nb=nb, resources=resources, km=km, **kwargs).execute()
           ^^^^^^^^^^^^^^^^^^^^^^^^^^^^^^^^^^^^^^^^^^^^^^^^^^^^^^^^^^^^^^^^^^^^^
  File "D:\Anaconda3\Lib\site-packages\jupyter_core\utils\__init__.py", line 165, in wrapped
    return loop.run_until_complete(inner)
           ^^^^^^^^^^^^^^^^^^^^^^^^^^^^^^
  File "D:\Anaconda3\Lib\asyncio\base_events.py", line 687, in run_until_complete
    return future.result()
           ^^^^^^^^^^^^^^^
  File "D:\Anaconda3\Lib\site-packages\nbclient\client.py", line 705, in async_execute
    await self.async_execute_cell(
  File "D:\Anaconda3\Lib\site-packages\nbclient\client.py", line 1058, in async_execute_cell
    await self._check_raise_for_error(cell, cell_index, exec_reply)
  File "D:\Anaconda3\Lib\site-packages\nbclient\client.py", line 914, in _check_raise_for_error
    raise CellExecutionError.from_cell_and_msg(cell, exec_reply_content)
nbclient.exceptions.CellExecutionError: An error occurred while executing the following cell:
------------------
import ipywidgets as widgets
file = open("../images/WidgetArch.png", "rb")
image = file.read()
widgets.Image(
    value=image,
    format='png',
    width=300,
    height=400,
)
------------------


[1;31m---------------------------------------------------------------------------[0m
[1;31mFileNotFoundError[0m                         Traceback (most recent call last)
Cell [1;32mIn[32], line 2[0m
[0;32m      1[0m [38;5;28;01mimport[39;00m [38;5;21;01mipywidgets[39;00m [38;5;28;01mas[39;00m [38;5;21;01mwidgets[39;00m
[1;32m----> 2[0m file [38;5;241m=[39m [38;5;28mopen[39m([38;5;124m"[39m[38;5;124m../images/WidgetArch.png[39m[38;5;124m"[39m, [38;5;124m"[39m[38;5;124mrb[39m[38;5;124m"[39m)
[0;32m      3[0m image [38;5;241m=[39m file[38;5;241m.[39mread()
[0;32m      4[0m widgets[38;5;241m.[39mImage(
[0;32m      5[0m     value[38;5;241m=[39mimage,
[0;32m      6[0m     [38;5;28mformat[39m[38;5;241m=[39m[38;5;124m'[39m[38;5;124mpng[39m[38;5;124m'[39m,
[0;32m      7[0m     width[38;5;241m=[39m[38;5;241m300[39m,
[0;32m      8[0m     height[38;5;241m=[39m[38;5;241m400[39m,
[0;32m      9[0m )

File [1;32mD:\Anaconda3\Lib\site-packages\IPython\core\interactiveshell.py:324[0m, in [0;36m_modified_open[1;34m(file, *args, **kwargs)[0m
[0;32m    317[0m [38;5;28;01mif[39;00m file [38;5;129;01min[39;00m {[38;5;241m0[39m, [38;5;241m1[39m, [38;5;241m2[39m}:
[0;32m    318[0m     [38;5;28;01mraise[39;00m [38;5;167;01mValueError[39;00m(
[0;32m    319[0m         [38;5;124mf[39m[38;5;124m"[39m[38;5;124mIPython won[39m[38;5;124m'[39m[38;5;124mt let you open fd=[39m[38;5;132;01m{[39;00mfile[38;5;132;01m}[39;00m[38;5;124m by default [39m[38;5;124m"[39m
[0;32m    320[0m         [38;5;124m"[39m[38;5;124mas it is likely to crash IPython. If you know what you are doing, [39m[38;5;124m"[39m
[0;32m    321[0m         [38;5;124m"[39m[38;5;124myou can use builtins[39m[38;5;124m'[39m[38;5;124m open.[39m[38;5;124m"[39m
[0;32m    322[0m     )
[1;32m--> 324[0m [38;5;28;01mreturn[39;00m io_open(file, [38;5;241m*[39margs, [38;5;241m*[39m[38;5;241m*[39mkwargs)

[1;31mFileNotFoundError[0m: [Errno 2] No such file or directory: '../images/WidgetArch.png'

